<?xml version="1.0" ?>
<robot name="stella" xmlns:xacro="http://ros.org/wiki/xacro">

  <!-- Init colour -->
  <material name="black">
      <color rgba="0.0 0.0 0.0 1.0"/>
  </material>

  <material name="dark">
    <color rgba="0.3 0.3 0.3 1.0"/>
  </material>

  <material name="light_black">
    <color rgba="0.4 0.4 0.4 1.0"/>
  </material>

  <material name="blue">
    <color rgba="0.0 0.0 0.8 1.0"/>
  </material>

  <material name="green">
    <color rgba="0.0 0.8 0.0 1.0"/>
  </material>

  <material name="grey">
    <color rgba="0.5 0.5 0.5 1.0"/>
  </material>

  <material name="orange">
    <color rgba="1.0 0.4235 0.0392 1.0"/>
  </material>

  <material name="brown">
    <color rgba="0.8706 0.8118 0.7647 1.0"/>
  </material>

  <material name="red">
    <color rgba="0.8 0.0 0.0 1.0"/>
  </material>

  <material name="white">
    <color rgba="1.0 1.0 1.0 1.0"/>
  </material>

  <xacro:property name="base_width" value="0.545"/>
  <xacro:property name="base_length" value="0.68"/>
  <xacro:property name="base_height" value="0.3"/>

  <xacro:property name="wheel_radius" value="0.12"/>
  <xacro:property name="wheel_width" value="0.05"/>
  <xacro:property name="wheel_ygap" value="0.2125"/>
  <xacro:property name="wheel_zoff" value="0.0"/>
  <xacro:property name="wheel_xoff" value="0.2"/>
  <xacro:property name="lidar_xoff" value="0.1"/>
  <xacro:property name="imu_yoff" value="0.085"/>
  <xacro:property name="caster_xoff" value="0.14"/>


  <link name="base_footprint"/>


  <joint name="base_joint" type="fixed">
    <origin xyz="0.0 0.0 ${(wheel_radius)}" rpy="0 0 0"/>
    <parent link="base_footprint"/>
    <child link="base_link"/>
    <!-- <origin xyz="0.0 0.0 ${-(wheel_radius)}" rpy="0 0 0"/> -->
  </joint>

  <link name="base_link">
      <!-- <origin xyz ="0.0 0.0 ${(wheel_radius)}" rpy ="0 0 0"/> -->
    <visual>
      <origin xyz ="0.0 0.0 ${base_height/2}" rpy ="0 0 0"/>
      <geometry>
        <box size="${base_length} ${base_width} ${base_height}"/>
      </geometry>
      <material name="Cyan">
        <color rgba="0 1.0 1.0 1.0"/>
      </material>
    </visual>
  </link>





  <!-- Wheels -->
  <xacro:macro name="wheel" params="prefix x_reflect y_reflect">
    <link name="${prefix}_link">
      <visual>
        <origin xyz="0 0 0" rpy="${pi/2} 0 0"/>
        <geometry>
            <cylinder radius="${wheel_radius}" length="${wheel_width}"/>
        </geometry>
        <material name="Gray">
          <color rgba="0.5 0.5 0.5 1.0"/>
        </material>
      </visual>
    </link>

    <link name = "${prefix}_virtul_link"/>


    <!-- <joint name="{prefix}_virtul_joint" type="fixed">
      <origin xyz="0.0 0.0 0" rpy="0 0 0"/>
      <parent link="${prefix}_link"/>
      <child link="${prefix}_virtul_link"/>
    </joint> -->


    <joint name="${prefix}_omni_joint" type="continuous">
      <parent link="base_link"/>
      <child link="${prefix}_virtul_link"/>
      <origin xyz="${x_reflect*wheel_xoff} ${y_reflect*wheel_ygap} ${-wheel_zoff}" rpy="0 0 0"/>
      <axis xyz="0 0 1"/>
    </joint>

    <joint name="${prefix}_joint" type="continuous">
      <parent link="base_link"/>
      <child link="${prefix}_link"/>
      <origin xyz="${x_reflect*wheel_xoff} ${y_reflect*wheel_ygap} ${-wheel_zoff}" rpy="0 0 0"/>
      <axis xyz="0 1 0"/>
    </joint>

<!--
    <link name = "${prefix}_virtul_link"/>


    <joint name="${prefix}_omni_joint" type="continuous">
      <parent link="base_link"/>
      <child link="${prefix}_virtul_link">
      <origin xyz="${x_reflect*wheel_xoff} ${y_reflect*wheel_ygap} ${-wheel_zoff}" rpy="0 0 0"/>
      <axis xyz="0 0 1"/>
    </joint>


    <joint name="${prefix}_joint" type="continuous">
      <parent link="${prefix}_virtul_link"/>
      <child link="${prefix}_link"/>
      <origin xyz="${x_reflect*wheel_xoff} ${y_reflect*wheel_ygap} ${-wheel_zoff}" rpy="0 0 0"/>
      <axis xyz="0 1 0"/>
    </joint> -->


  </xacro:macro>

  <xacro:wheel prefix="drivewhl_fl" x_reflect="1" y_reflect="1" />
  <xacro:wheel prefix="drivewhl_fr" x_reflect="1" y_reflect="-1" />
  <xacro:wheel prefix="drivewhl_rl" x_reflect="-1" y_reflect="1" />
  <xacro:wheel prefix="drivewhl_rr" x_reflect="-1" y_reflect="-1" />




  <joint name="imu_joint" type="fixed">
    <parent link="base_link"/>
    <child link="imu_link"/>
    <origin xyz="${base_length/2 -lidar_xoff } ${-imu_yoff} ${base_height}" rpy="0.0 0.0 0.0"/>
  </joint>

  <link name="imu_link"/>

  <joint name="scan_joint" type="fixed">
    <parent link="base_link"/>
    <child link="base_scan"/>
    <origin xyz="${base_length/2 -lidar_xoff } 0.0 ${base_height}" rpy="0.0 0.0 0.0"/>
  </joint>

  <link name="base_scan" />

  <joint name="depth_camera_joint" type="fixed">
    <parent link="base_link"/>
    <child link="camera_link"/>
    <origin xyz="${base_length/2} 0.0 ${base_height}" rpy="0.0 0.0 0.0"/>
  </joint>

  <link name="camera_link" />

  <joint name="gps_joint" type="fixed">
    <parent link="base_link"/>
    <child link="gps_link"/>
    <origin xyz="${base_length/2 } ${imu_yoff} ${base_height}" rpy="0.0 0.0 0.0"/>
  </joint>


  <link name="gps_link" />
</robot>
